Workbook

Sheet GiaDinh
A1: MÔ HÌNH KINH TẾ – ỨNG DỤNG GIA SƯ AI "THẦY AN"
A2: Bảng giả định (ô xanh = nhập tay, chỉnh tự do; ô đen = công thức)
A4: A. Tỷ giá & đơn giá token
A5: Tỷ giá USD/VND | B5: 26000 | C5: Tham số, chỉnh theo tỷ giá thực tế
A6: Sonnet 4.6 – input ($/triệu token) | B6: 3 | C6: Nguồn: Anthropic 2026
A7: Sonnet 4.6 – output ($/triệu token) | B7: 15 | C7: Nguồn: Anthropic 2026
A8: Haiku 4.5 – input ($/triệu token) | B8: 1 | C8: Nguồn: Anthropic 2026
A9: Haiku 4.5 – output ($/triệu token) | B9: 5 | C9: Nguồn: Anthropic 2026
A10: Cache read = % giá input | B10: 0.1 | C10: Cache giảm ~90% chi phí input
A11: B. Token mỗi câu hỏi (gộp các lượt hội thoại)
A12: Input token – mới (không cache) | B12: 3500 | C12: Đề bài + lượt mới
A13: Input token – đọc từ cache | B13: 5000 | C13: System prompt + lịch sử + đề phổ biến
A14: Output token | B14: 1200 | C14: Dạy gợi mở → output ngắn
A15: Phụ trội kiểm chứng/giải lại (%) | B15: 0.1 | C15: ≈10% câu phải giải lại
A16: C. Định tuyến mô hình & chi phí khác
A17: % câu dùng Sonnet – người TRẢ PHÍ | B17: 0.7 | C17: Còn lại dùng Haiku
A18: % câu dùng Sonnet – người MIỄN PHÍ | B18: 0 | C18: Free: 100% Haiku để tiết kiệm
A19: Chi phí OCR / câu hỏi (VND) | B19: 0 | C19: Dùng vision; Mathpix là tùy chọn
A20: D. Mức sử dụng
A21: Câu hỏi/tháng – người TRẢ PHÍ | B21: 100 | C21: ≈3–4 câu/ngày khi học
A22: Câu hỏi/tháng – người MIỄN PHÍ | B22: 20 | C22: Đã giới hạn gói free
A23: E. Giá gói & thanh toán
A24: ARPU người trả phí (VND/tháng) | B24: 129000 | C24: Blended: Standard 99k + Premium 199k
A25: Phí cổng thanh toán (%) | B25: 0.02 | C25: Ví/cổng ~1–2%; VietQR/A2A ~0%
A26: F. Phễu & tăng trưởng
A27: Tỷ lệ chuyển đổi free→paid (%) | B27: 0.06 | C27: Đòn bẩy sống còn
A28: Churn người trả phí/tháng (%) | B28: 0.08
A29: Churn người miễn phí/tháng (%) | B29: 0.15
A30: CAC mỗi người dùng mới (VND) | B30: 60000 | C30: Chi phí thu hút
A31: Người dùng mới – tháng 1 | B31: 1000
A32: Tăng trưởng người dùng mới/tháng (%) | B32: 0.2
A33: G. Chi phí cố định/tháng
A34: Lương đội ngũ (VND/tháng) | B34: 80000000 | C34: ≈4–6 người giai đoạn đầu
A35: Hạ tầng & dịch vụ (VND/tháng) | B35: 15000000
A36: Chi phí cố định khác (VND/tháng) | B36: 10000000
A37: H. Phân khúc TINH HOA (Olympiad) — giả định riêng
A38: Opus 4.8 – input ($/triệu token) | B38: 5 | C38: Bậc reasoning hàng đầu
A39: Opus 4.8 – output ($/triệu token) | B39: 25 | C39: Nguồn: Anthropic 2026
A40: Input token mới/câu (đề + RAG) | B40: 6000
A41: Input token cache/câu (tài liệu + system) | B41: 8000
...

Sheet DonViKinhTe
A1: ĐƠN VỊ KINH TẾ (mỗi câu hỏi / mỗi người dùng)
A3: 1. Chi phí token mỗi câu hỏi (VND)
A4: Chi phí/câu – Sonnet | B4: =(GiaDinh!$B$12*GiaDinh!$B$6+GiaDinh!$B$13*GiaDinh!$B$6*GiaDinh!$B$10+GiaDinh!$B$14*GiaDinh!$B$7)/1000000*GiaDinh!$B$5 -> 780 | C4: fresh + cache + output
A5: Chi phí/câu – Haiku | B5: =(GiaDinh!$B$12*GiaDinh!$B$8+GiaDinh!$B$13*GiaDinh!$B$8*GiaDinh!$B$10+GiaDinh!$B$14*GiaDinh!$B$9)/1000000*GiaDinh!$B$5 -> 260
A6: Chi phí/câu – người TRẢ PHÍ (đã định tuyến + kiểm chứng) | B6: =(GiaDinh!$B$17*B4+(1-GiaDinh!$B$17)*B5)*(1+GiaDinh!$B$15)+GiaDinh!$B$19 -> 686.4 | C6: blend Sonnet/Haiku
A7: Chi phí/câu – người MIỄN PHÍ | B7: =(GiaDinh!$B$18*B4+(1-GiaDinh!$B$18)*B5)*(1+GiaDinh!$B$15)+GiaDinh!$B$19 -> 286 | C7: free: 100% Haiku
A8: 2. Theo mỗi người dùng / tháng (VND)
A9: Chi phí LLM – mỗi người TRẢ PHÍ | B9: =GiaDinh!$B$21*B6 -> 68640
A10: Chi phí LLM – mỗi người MIỄN PHÍ | B10: =GiaDinh!$B$22*B7 -> 5720
A11: Doanh thu ròng/người trả phí (trừ phí TT) | B11: =GiaDinh!$B$24*(1-GiaDinh!$B$25) -> 126420
A12: Lợi nhuận gộp/người trả phí | B12: =B11-B9 -> 57780 | C12: Chưa tính gánh nặng free
A13: Biên lợi nhuận gộp (%) | B13: =B12/B11 -> 0.45704794
A14: 3. Phễu freemium & LTV
A15: Số người miễn phí 'gánh' mỗi người trả phí | B15: =(1-GiaDinh!$B$27)/GiaDinh!$B$27 -> 15.666667 | C15: theo (1-conv)/conv
A16: Gánh nặng LLM free phân bổ/người trả phí/tháng | B16: =B15*B10 -> 89613.333
A17: Đóng góp ròng/người trả phí (đã trừ free burn) | B17: =B12-B16 -> -31833.333 | C17: SỐ QUYẾT ĐỊNH lời/lỗ
A18: Vòng đời người trả phí (tháng) | B18: =1/GiaDinh!$B$28 -> 12.5 | C18: theo 1/churn
A19: LTV/người trả phí (gộp) | B19: =B12*B18 -> 722250
A20: CAC thực/mỗi người trả phí | B20: =GiaDinh!$B$30/GiaDinh!$B$27 -> 1000000 | C20: theo CAC/conv
A21: Tỷ lệ LTV : CAC | B21: =B19/B20 -> 0.72225 | C21: Mục tiêu ≥ 3.0x
A22: Thời gian hoàn vốn CAC (tháng) | B22: =IF(B12>0,B20/B12,9999) -> 17.307027

Sheet DuBao
A1: DỰ BÁO TÀI CHÍNH 24 THÁNG (VND)
A3: Tháng | B3: T1 | C3: T2 | D3: T3 | E3: T4 | F3: T5 | G3: T6 | H3: T7 | I3: T8 | J3: T9 | K3: T10 | L3: T11 | M3: T12 | N3: T13 | O3: T14 | P3: T15 | Q3: T16 | R3: T17 | S3: T18 | T3: T19 | U3: T20 | V3: T21 | W3: T22 | X3: T23 | Y3: T24
A4: Người dùng mới | B4: =GiaDinh!$B$31 -> 1000 | C4: =B4*(1+GiaDinh!$B$32) -> 1200 | D4: =C4*(1+GiaDinh!$B$32) -> 1440 | E4: =D4*(1+GiaDinh!$B$32) -> 1728 | F4: =E4*(1+GiaDinh!$B$32) -> 2073.6 | G4: =F4*(1+GiaDinh!$B$32) -> 2488.32 | H4: =G4*(1+GiaDinh!$B$32) -> 2985.984 | I4: =H4*(1+GiaDinh!$B$32) -> 3583.1808 | J4: =I4*(1+GiaDinh!$B$32) -> 4299.817 | ... Y4: =X4*(1+GiaDinh!$B$32) -> 66247.373
A5: Chuyển đổi sang trả phí | B5: =B4*GiaDinh!$B$27 -> 60 | C5: =C4*GiaDinh!$B$27 -> 72 | D5: =D4*GiaDinh!$B$27 -> 86.4 | E5: =E4*GiaDinh!$B$27 -> 103.68 | F5: =F4*GiaDinh!$B$27 -> 124.416 | G5: =G4*GiaDinh!$B$27 -> 149.2992 | H5: =H4*GiaDinh!$B$27 -> 179.15904 | I5: =I4*GiaDinh!$B$27 -> 214.99085 | ... Y5: =Y4*GiaDinh!$B$27 -> 3974.8424
A6: Người TRẢ PHÍ (cuối kỳ) | B6: =B5 -> 60 | C6: =B6*(1-GiaDinh!$B$28)+C5 -> 127.2 | D6: =C6*(1-GiaDinh!$B$28)+D5 -> 203.424 | E6: =D6*(1-GiaDinh!$B$28)+E5 -> 290.83008 | F6: =E6*(1-GiaDinh!$B$28)+F5 -> 391.97967 | G6: =F6*(1-GiaDinh!$B$28)+G5 -> 509.9205 | H6: =G6*(1-GiaDinh!$B$28)+H5 -> 648.2859 | I6: =H6*(1-GiaDinh!$B$28)+I5 -> 811.41388 | J6: =I6*(1-GiaDinh!$B$28)+J5 -> 1004.4898 | ... Y6: =X6*(1-GiaDinh!$B$28)+Y5 -> 17006.072
A7: Người MIỄN PHÍ (cuối kỳ) | B7: =B4-B5 -> 940 | C7: =B7*(1-GiaDinh!$B$29)+C4-C5 -> 1927 | D7: =C7*(1-GiaDinh!$B$29)+D4-D5 -> 2991.55 | E7: =D7*(1-GiaDinh!$B$29)+E4-E5 -> 4167.1375 | F7: =E7*(1-GiaDinh!$B$29)+F4-F5 -> 5491.2509 | G7: =F7*(1-GiaDinh!$B$29)+G4-G5 -> 7006.584 | H7: =G7*(1-GiaDinh!$B$29)+H4-H5 -> 8762.4214 | I7: =H7*(1-GiaDinh!$B$29)+I4-I5 -> 10816.248 | J7: =I7*(1-GiaDinh!$B$29)+J4-J5 -> 13235.639 | ... Y7: =X7*(1-GiaDinh!$B$29)+Y4-Y5 -> 213451.48
A9: Doanh thu | B9: =B6*GiaDinh!$B$24 -> 7740000 | C9: =C6*GiaDinh!$B$24 -> 16408800 | D9: =D6*GiaDinh!$B$24 -> 26241696 | E9: =E6*GiaDinh!$B$24 -> 37517080 | F9: =F6*GiaDinh!$B$24 -> 50565378 | G9: =G6*GiaDinh!$B$24 -> 65779744 | H9: =H6*GiaDinh!$B$24 -> 83628881 | I9: =I6*GiaDinh!$B$24 -> 1.0467239e+08 | ... Y9: =Y6*GiaDinh!$B$24 -> 2.1937833e+09
A10: (-) Phí thanh toán | B10: =-B9*GiaDinh!$B$25 -> -154800 | C10: =-C9*GiaDinh!$B$25 -> -328176 | D10: =-D9*GiaDinh!$B$25 -> -524833.92 | E10: =-E9*GiaDinh!$B$25 -> -750341.61 | F10: =-F9*GiaDinh!$B$25 -> -1011307.6 | G10: =-G9*GiaDinh!$B$25 -> -1315594.9 | H10: =-H9*GiaDinh!$B$25 -> -1672577.6 | I10: =-I9*GiaDinh!$B$25 -> -2093447.8 | ... Y10: =-Y9*GiaDinh!$B$25 -> -43875665
A11: (-) LLM – trả phí | B11: =-B6*DonViKinhTe!$B$9 -> -4118400 | C11: =-C6*DonViKinhTe!$B$9 -> -8731008 | D11: =-D6*DonViKinhTe!$B$9 -> -13963023 | E11: =-E6*DonViKinhTe!$B$9 -> -19962577 | F11: =-F6*DonViKinhTe!$B$9 -> -26905485 | G11: =-G6*DonViKinhTe!$B$9 -> -35000943 | H11: =-H6*DonViKinhTe!$B$9 -> -44498344 | I11: =-I6*DonViKinhTe!$B$9 -> -55695448 | ... Y11: =-Y6*DonViKinhTe!$B$9 -> -1.1672968e+09
A12: (-) LLM – miễn phí | B12: =-B7*DonViKinhTe!$B$10 -> -5376800 | C12: =-C7*DonViKinhTe!$B$10 -> -11022440 | D12: =-D7*DonViKinhTe!$B$10 -> -17111666 | E12: =-E7*DonViKinhTe!$B$10 -> -23836026 | F12: =-F7*DonViKinhTe!$B$10 -> -31409955 | G12: =-G7*DonViKinhTe!$B$10 -> -40077661 | H12: =-H7*DonViKinhTe!$B$10 -> -50121050 | I12: =-I7*DonViKinhTe!$B$10 -> -61868939 | ... Y12: =-Y7*DonViKinhTe!$B$10 -> -1.2209425e+09
A13: Lợi nhuận gộp | B13: =B9+B10+B11+B12 -> -1910000 | C13: =C9+C10+C11+C12 -> -3672824 | D13: =D9+D10+D11+D12 -> -5357827.3 | E13: =E9+E10+E11+E12 -> -7031864.5 | F13: =F9+F10+F11+F12 -> -8761369.5 | G13: =G9+G10+G11+G12 -> -10614454 | H13: =H9+H10+H11+H12 -> -12663091 | I13: =I9+I10+I11+I12 -> -14985446 | ... Y13: =Y9+Y10+Y11+Y12 -> -2.3833163e+08
A15: (-) Marketing/CAC | B15: =-B4*GiaDinh!$B$30 -> -60000000 | C15: =-C4*GiaDinh!$B$30 -> -72000000 | D15: =-D4*GiaDinh!$B$30 -> -86400000 | E15: =-E4*GiaDinh!$B$30 -> -103680000 | F15: =-F4*GiaDinh!$B$30 -> -124416000 | G15: =-G4*GiaDinh!$B$30 -> -149299200 | H15: =-H4*GiaDinh!$B$30 -> -179159040 | I15: =-I4*GiaDinh!$B$30 -> -214990848 | ... Y15: =-Y4*GiaDinh!$B$30 -> -3.9748424e+09
A16: (-) Lương đội ngũ | B16: =-GiaDinh!$B$34 -> -80000000 | C16: =-GiaDinh!$B$34 -> -80000000 | D16: =-GiaDinh!$B$34 -> -80000000 | E16: =-GiaDinh!$B$34 -> -80000000 | F16: =-GiaDinh!$B$34 -> -80000000 | G16: =-GiaDinh!$B$34 -> -80000000 | H16: =-GiaDinh!$B$34 -> -80000000 | I16: =-GiaDinh!$B$34 -> -80000000 | ... Y16: =-GiaDinh!$B$34 -> -80000000
A17: (-) Hạ tầng | B17: =-GiaDinh!$B$35 -> -15000000 | C17: =-GiaDinh!$B$35 -> -15000000 | D17: =-GiaDinh!$B$35 -> -15000000 | E17: =-GiaDinh!$B$35 -> -15000000 | F17: =-GiaDinh!$B$35 -> -15000000 | G17: =-GiaDinh!$B$35 -> -15000000 | H17: =-GiaDinh!$B$35 -> -15000000 | I17: =-GiaDinh!$B$35 -> -15000000 | ... Y17: =-GiaDinh!$B$35 -> -15000000
A18: (-) Chi phí khác | B18: =-GiaDinh!$B$36 -> -10000000 | C18: =-GiaDinh!$B$36 -> -10000000 | D18: =-GiaDinh!$B$36 -> -10000000 | E18: =-GiaDinh!$B$36 -> -10000000 | F18: =-GiaDinh!$B$36 -> -10000000 | G18: =-GiaDinh!$B$36 -> -10000000 | H18: =-GiaDinh!$B$36 -> -10000000 | I18: =-GiaDinh!$B$36 -> -10000000 | ... Y18: =-GiaDinh!$B$36 -> -10000000
A19: EBITDA | B19: =B13+B15+B16+B17+B18 -> -166910000 | C19: =C13+C15+C16+C17+C18 -> -180672824 | D19: =D13+D15+D16+D17+D18 -> -1.9675783e+08 | E19: =E13+E15+E16+E17+E18 -> -2.1571186e+08 | F19: =F13+F15+F16+F17+F18 -> -2.3817737e+08 | G19: =G13+G15+G16+G17+G18 -> -2.6491365e+08 | H19: =H13+H15+H16+H17+H18 -> -2.9682213e+08 | I19: =I13+I15+I16+I17+I18 -> -3.3497629e+08 | ... Y19: =Y13+Y15+Y16+Y17+Y18 -> -4.318174e+09
A20: Dòng tiền lũy kế | B20: =B19 -> -166910000 | C20: =B20+C19 -> -347582824 | D20: =C20+D19 -> -5.4434065e+08 | E20: =D20+E19 -> -7.6005252e+08 | F20: =E20+F19 -> -9.9822989e+08 | G20: =F20+G19 -> -1.2631435e+09 | H20: =G20+H19 -> -1.5599657e+09 | I20: =H20+I19 -> -1.894942e+09 | J20: =I20+J19 -> -2.2755994e+09 | ... Y20: =X20+Y19 -> -2.7510829e+10
A21: >0? | B21: =IF(B19>0,1,0) -> 0 | C21: =IF(C19>0,1,0) -> 0 | D21: =IF(D19>0,1,0) -> 0 | E21: =IF(E19>0,1,0) -> 0 | F21: =IF(F19>0,1,0) -> 0 | G21: =IF(G19>0,1,0) -> 0 | H21: =IF(H19>0,1,0) -> 0 | I21: =IF(I19>0,1,0) -> 0 | ... Y21: =IF(Y19>0,1,0) -> 0
A22: >0? | B22: =IF(B20>0,1,0) -> 0 | C22: =IF(C20>0,1,0) -> 0 | D22: =IF(D20>0,1,0) -> 0 | E22: =IF(E20>0,1,0) -> 0 | F22: =IF(F20>0,1,0) -> 0 | G22: =IF(G20>0,1,0) -> 0 | H22: =IF(H20>0,1,0) -> 0 | I22: =IF(I20>0,1,0) -> 0 | ... Y22: =IF(Y20>0,1,0) -> 0
A24: TÓM TẮT
A25: Doanh thu năm 1 (T1–12) | B25: =SUM(B9:M9) -> 1.1119275e+09
A26: EBITDA năm 1 | B26: =SUM(B19:M19) -> -3.7917761e+09
A27: Doanh thu năm 2 (T13–24) | B27: =SUM(N9:Y9) -> 1.1632415e+10
A28: EBITDA năm 2 | B28: =SUM(N19:Y19) -> -2.3719053e+10
A29: Tháng EBITDA dương đầu tiên | B29: =IFERROR(MATCH(1,B21:Y21,0),"chưa") -> chưa
A30: Tháng hòa vốn dòng tiền lũy kế | B30: =IFERROR(MATCH(1,B22:Y22,0),"chưa") -> chưa
A31: Người trả phí cuối T24 | B31: =Y6 -> 17006.072

Sheet DoNhay
A1: ĐỘ NHẠY – Biên lợi nhuận gộp/người trả phí
A2: Hàng = giá gói (ARPU); Cột = số câu hỏi/tháng. (Dùng định tuyến & token theo sheet Giả định)
A4: ARPU \ Câu hỏi/tháng | B4: 60 | C4: 100 | D4: 150 | E4: 200
A5: 79000 | B5: =($A5*(1-GiaDinh!$B$25)-B$4*DonViKinhTe!$B$6)/($A5*(1-GiaDinh!$B$25)) -> 0.46804443 | C5: =($A5*(1-GiaDinh!$B$25)-C$4*DonViKinhTe!$B$6)/($A5*(1-GiaDinh!$B$25)) -> 0.11340739 | D5: =($A5*(1-GiaDinh!$B$25)-D$4*DonViKinhTe!$B$6)/($A5*(1-GiaDinh!$B$25)) -> -0.32988892 | E5: =($A5*(1-GiaDinh!$B$25)-E$4*DonViKinhTe!$B$6)/($A5*(1-GiaDinh!$B$25)) -> -0.77318522
A6: 99000 | B6: =($A6*(1-GiaDinh!$B$25)-B$4*DonViKinhTe!$B$6)/($A6*(1-GiaDinh!$B$25)) -> 0.5755102 | C6: =($A6*(1-GiaDinh!$B$25)-C$4*DonViKinhTe!$B$6)/($A6*(1-GiaDinh!$B$25)) -> 0.29251701 | D6: =($A6*(1-GiaDinh!$B$25)-D$4*DonViKinhTe!$B$6)/($A6*(1-GiaDinh!$B$25)) -> -0.06122449 | E6: =($A6*(1-GiaDinh!$B$25)-E$4*DonViKinhTe!$B$6)/($A6*(1-GiaDinh!$B$25)) -> -0.41496599
A7: 129000 | B7: =($A7*(1-GiaDinh!$B$25)-B$4*DonViKinhTe!$B$6)/($A7*(1-GiaDinh!$B$25)) -> 0.67422876 | C7: =($A7*(1-GiaDinh!$B$25)-C$4*DonViKinhTe!$B$6)/($A7*(1-GiaDinh!$B$25)) -> 0.45704794 | D7: =($A7*(1-GiaDinh!$B$25)-D$4*DonViKinhTe!$B$6)/($A7*(1-GiaDinh!$B$25)) -> 0.1855719 | E7: =($A7*(1-GiaDinh!$B$25)-E$4*DonViKinhTe!$B$6)/($A7*(1-GiaDinh!$B$25)) -> -0.085904129
A8: 159000 | B8: =($A8*(1-GiaDinh!$B$25)-B$4*DonViKinhTe!$B$6)/($A8*(1-GiaDinh!$B$25)) -> 0.73569503 | C8: =($A8*(1-GiaDinh!$B$25)-C$4*DonViKinhTe!$B$6)/($A8*(1-GiaDinh!$B$25)) -> 0.55949172 | D8: =($A8*(1-GiaDinh!$B$25)-D$4*DonViKinhTe!$B$6)/($A8*(1-GiaDinh!$B$25)) -> 0.33923758 | E8: =($A8*(1-GiaDinh!$B$25)-E$4*DonViKinhTe!$B$6)/($A8*(1-GiaDinh!$B$25)) -> 0.11898344
A9: 199000 | B9: =($A9*(1-GiaDinh!$B$25)-B$4*DonViKinhTe!$B$6)/($A9*(1-GiaDinh!$B$25)) -> 0.78882166 | C9: =($A9*(1-GiaDinh!$B$25)-C$4*DonViKinhTe!$B$6)/($A9*(1-GiaDinh!$B$25)) -> 0.6480361 | D9: =($A9*(1-GiaDinh!$B$25)-D$4*DonViKinhTe!$B$6)/($A9*(1-GiaDinh!$B$25)) -> 0.47205415 | E9: =($A9*(1-GiaDinh!$B$25)-E$4*DonViKinhTe!$B$6)/($A9*(1-GiaDinh!$B$25)) -> 0.2960722
A11: Đọc bảng: ô càng cao càng lời; ô âm = lỗ ở mức giá/sử dụng đó.
A12: Đòn bẩy chính: tăng % cache, giảm output (dạy gợi mở), định tuyến Haiku, và siết hạn mức gói free.

Sheet TinhHoa
A1: PHÂN KHÚC TINH HOA (OLYMPIAD) — KINH TẾ B2B
A2: Chi phí/câu cao (Opus + cross-check + HLV) nhưng KHÔNG có free-burn; bán B2B giá cao.
A4: 1. Chi phí mỗi câu hỏi (VND)
A5: Chi phí LLM/câu – Opus (bậc reasoning) | B5: =(GiaDinh!$B$40*GiaDinh!$B$38+GiaDinh!$B$41*GiaDinh!$B$38*GiaDinh!$B$10+GiaDinh!$B$42*GiaDinh!$B$39)/1000000*GiaDinh!$B$5 -> 4784 | C5: fresh + cache + output dài
A6: Chi phí LLM/câu + cross-check | B6: =B5*(1+GiaDinh!$B$43) -> 7176 | C6: câu quan trọng ×2
A7: Chi phí HLV duyệt/câu (phân bổ) | B7: =GiaDinh!$B$44*GiaDinh!$B$45*(GiaDinh!$B$46/60) -> 7500 | C7: tỷ lệ duyệt × phút × đơn giá
A8: Tổng chi phí/câu – tinh hoa | B8: =B6+B7 -> 14676
A9: 2. Theo mỗi chỗ (seat) / tháng
A10: Chi phí/chỗ/tháng | B10: =GiaDinh!$B$47*B8 -> 880560
A11: Doanh thu ròng/chỗ/tháng (trừ phí) | B11: =GiaDinh!$B$48*(1-GiaDinh!$B$49) -> 298500
A12: Lợi nhuận gộp/chỗ/tháng | B12: =B11-B10 -> -582060 | C12: KHÔNG có free-burn
A13: Biên lợi nhuận gộp (%) | B13: =B12/B11 -> -1.9499497
A14: Lợi nhuận gộp/chỗ/năm | B14: =B12*12 -> -6984720
A15: 3. Kịch bản B2B
A16: Tổng số chỗ | B16: =GiaDinh!$B$50*GiaDinh!$B$51 -> 500 | C16: trường × chỗ
A17: Doanh thu/tháng | B17: =B16*GiaDinh!$B$48 -> 150000000
A18: Chi phí LLM+HLV/tháng | B18: =B16*B10 -> 440280000
A19: Phí thanh toán/tháng | B19: =B17*GiaDinh!$B$49 -> 750000
A20: Lợi nhuận gộp/tháng | B20: =B17-B18-B19 -> -291030000
A21: EBITDA/tháng (trừ cố định riêng) | B21: =B20-GiaDinh!$B$52 -> -311030000
A22: Doanh thu/năm | B22: =B17*12 -> 1800000000
A23: EBITDA/năm | B23: =B21*12 -> -3732360000
A24: Số chỗ hòa vốn cố định riêng | B24: =IF(B12>0,GiaDinh!$B$52/B12,9999) -> 9999 | C24: cố định ÷ GP mỗi chỗ
A25: 4. So sánh hai phân khúc
A26: Chi phí/câu – Đại trà | B26: =DonViKinhTe!$B$6 -> 686.4
A27: Chi phí/câu – Tinh hoa | B27: =B8 -> 14676 | C27: cao hơn nhiều
A28: LN gộp/người/tháng – Đại trà | B28: =DonViKinhTe!$B$12 -> 57780 | C28: chưa trừ free-burn
A29: LN gộp/chỗ/tháng – Tinh hoa | B29: =B12 -> -582060 | C29: B2B, không free-burn
A31: Khác biệt cốt lõi: Đại trà = chi phí/câu thấp NHƯNG bị free-burn + chuyển đổi thấp;
A32: Tinh hoa = chi phí/câu cao (Opus + cross-check + HLV) NHƯNG bán B2B, không free-burn, WTP cao.
A34: 5. Độ nhạy — Biên lợi nhuận gộp/chỗ
A35: Hàng = giá/chỗ/tháng; Cột = câu hỏi/tháng
A36: Giá \ Câu hỏi | B36: 40 | C36: 60 | D36: 80 | E36: 100
A37: 200000 | B37: =($A37*(1-GiaDinh!$B$49)-B$36*B8)/($A37*(1-GiaDinh!$B$49)) -> -1.9499497 | C37: =($A37*(1-GiaDinh!$B$49)-C$36*B8)/($A37*(1-GiaDinh!$B$49)) -> -3.4249246 | D37: =($A37*(1-GiaDinh!$B$49)-D$36*B8)/($A37*(1-GiaDinh!$B$49)) -> -4.8998995 | E37: =($A37*(1-GiaDinh!$B$49)-E$36*B8)/($A37*(1-GiaDinh!$B$49)) -> -6.3748744
A38: 300000 | B38: =($A38*(1-GiaDinh!$B$49)-B$36*B8)/($A38*(1-GiaDinh!$B$49)) -> -0.96663317 | C38: =($A38*(1-GiaDinh!$B$49)-C$36*B8)/($A38*(1-GiaDinh!$B$49)) -> -1.9499497 | D38: =($A38*(1-GiaDinh!$B$49)-D$36*B8)/($A38*(1-GiaDinh!$B$49)) -> -2.9332663 | E38: =($A38*(1-GiaDinh!$B$49)-E$36*B8)/($A38*(1-GiaDinh!$B$49)) -> -3.9165829
A39: 400000 | B39: =($A39*(1-GiaDinh!$B$49)-B$36*B8)/($A39*(1-GiaDinh!$B$49)) -> -0.47497487 | C39: =($A39*(1-GiaDinh!$B$49)-C$36*B8)/($A39*(1-GiaDinh!$B$49)) -> -1.2124623 | D39: =($A39*(1-GiaDinh!$B$49)-D$36*B8)/($A39*(1-GiaDinh!$B$49)) -> -1.9499497 | E39: =($A39*(1-GiaDinh!$B$49)-E$36*B8)/($A39*(1-GiaDinh!$B$49)) -> -2.6874372
A40: 500000 | B40: =($A40*(1-GiaDinh!$B$49)-B$36*B8)/($A40*(1-GiaDinh!$B$49)) -> -0.1799799 | C40: =($A40*(1-GiaDinh!$B$49)-C$36*B8)/($A40*(1-GiaDinh!$B$49)) -> -0.76996985 | D40: =($A40*(1-GiaDinh!$B$49)-D$36*B8)/($A40*(1-GiaDinh!$B$49)) -> -1.3599598 | E40: =($A40*(1-GiaDinh!$B$49)-E$36*B8)/($A40*(1-GiaDinh!$B$49)) -> -1.9499497
